<?xml version="1.0"?>
<robot name="double_pendulum_custom">
  <link name="base"/>

  <link name="link1">
    <inertial>
      <origin xyz="0 -0.5 0" rpy="0 0 0"/>
      <mass value="1.0"/>
      <inertia ixx="0.01" iyy="0.01" izz="0.01" ixy="0" ixz="0" iyz="0"/>
    </inertial>
    <visual>
      <origin xyz="0 -0.5 0" rpy="0 0 0"/>
      <geometry>
        <box size="0.05 1.0 0.05"/>
      </geometry>
      <material name="blue">
        <color rgba="0 0 1 1"/>
      </material>
    </visual>
    <collision>
      <origin xyz="0 -0.5 0" rpy="0 0 0"/>
      <geometry>
        <box size="0.05 1.0 0.05"/>
      </geometry>
    </collision>
  </link>

  <link name="link2">
    <inertial>
      <origin xyz="0 -0.5 0" rpy="0 0 0"/>
      <mass value="1.0"/>
      <inertia ixx="0.01" iyy="0.01" izz="0.01" ixy="0" ixz="0" iyz="0"/>
    </inertial>
    <visual>
      <origin xyz="0 -0.5 0" rpy="0 0 0"/>
      <geometry>
        <box size="0.05 1.0 0.05"/>
      </geometry>
      <material name="green">
        <color rgba="0 1 0 1"/>
      </material>
    </visual>
    <collision>
      <origin xyz="0 -0.5 0" rpy="0 0 0"/>
      <geometry>
        <box size="0.05 1.0 0.05"/>
      </geometry>
    </collision>
  </link>

  <!-- Joint 1: base -> link1, revolute about z -->
  <joint name="joint1" type="revolute">
    <parent link="base"/>
    <child link="link1"/>
    <origin xyz="0 0 0" rpy="0 0 0"/>
    <axis xyz="0 0 1"/>
    <limit lower="-3.14" upper="3.14" effort="0" velocity="0"/>
  </joint>

  <!-- Joint 2: link1 -> link2, revolute about z at end of link1 -->
  <joint name="joint2" type="revolute">
    <parent link="link1"/>
    <child link="link2"/>
    <origin xyz="0 -1.0 0" rpy="0 0 0"/>
    <axis xyz="0 0 1"/>
    <limit lower="-3.14" upper="3.14" effort="0" velocity="0"/>
  </joint>
</robot>